2021-05-19 18:02:20,812 ERROR: Exception on /explore [GET] [in /home/szwhite/shayblog/sbvenv/lib/python3.8/site-packages/flask/app.py:1891]
Traceback (most recent call last):
  File "/home/szwhite/shayblog/sbvenv/lib/python3.8/site-packages/flask/app.py", line 2447, in wsgi_app
    response = self.full_dispatch_request()
  File "/home/szwhite/shayblog/sbvenv/lib/python3.8/site-packages/flask/app.py", line 1952, in full_dispatch_request
    rv = self.handle_user_exception(e)
  File "/home/szwhite/shayblog/sbvenv/lib/python3.8/site-packages/flask/app.py", line 1821, in handle_user_exception
    reraise(exc_type, exc_value, tb)
  File "/home/szwhite/shayblog/sbvenv/lib/python3.8/site-packages/flask/_compat.py", line 39, in reraise
    raise value
  File "/home/szwhite/shayblog/sbvenv/lib/python3.8/site-packages/flask/app.py", line 1950, in full_dispatch_request
    rv = self.dispatch_request()
  File "/home/szwhite/shayblog/sbvenv/lib/python3.8/site-packages/flask/app.py", line 1936, in dispatch_request
    return self.view_functions[rule.endpoint](**req.view_args)
  File "/home/szwhite/shayblog/sbvenv/lib/python3.8/site-packages/flask_login/utils.py", line 272, in decorated_view
    return func(*args, **kwargs)
  File "/home/szwhite/shayblog/myapp/main/routes.py", line 51, in explore
    return render_template('index.html', title='Explore', posts=posts.items, next_url=next_url, prev_url=prev_url)
  File "/home/szwhite/shayblog/sbvenv/lib/python3.8/site-packages/flask/templating.py", line 137, in render_template
    return _render(
  File "/home/szwhite/shayblog/sbvenv/lib/python3.8/site-packages/flask/templating.py", line 120, in _render
    rv = template.render(context)
  File "/home/szwhite/shayblog/sbvenv/lib/python3.8/site-packages/jinja2/environment.py", line 1090, in render
    self.environment.handle_exception()
  File "/home/szwhite/shayblog/sbvenv/lib/python3.8/site-packages/jinja2/environment.py", line 832, in handle_exception
    reraise(*rewrite_traceback_stack(source=source))
  File "/home/szwhite/shayblog/sbvenv/lib/python3.8/site-packages/jinja2/_compat.py", line 28, in reraise
    raise value.with_traceback(tb)
  File "/home/szwhite/shayblog/myapp/templates/index.html", line 2, in top-level template code
    {% import 'bootstrap/wtf.html' as wtf %}
  File "/home/szwhite/shayblog/myapp/templates/base.html", line 1, in top-level template code
    {% extends 'bootstrap/base.html' %}
  File "/home/szwhite/shayblog/sbvenv/lib/python3.8/site-packages/flask_bootstrap/templates/bootstrap/base.html", line 1, in top-level template code
    {% block doc -%}
  File "/home/szwhite/shayblog/sbvenv/lib/python3.8/site-packages/flask_bootstrap/templates/bootstrap/base.html", line 4, in block "doc"
    {%- block html %}
  File "/home/szwhite/shayblog/sbvenv/lib/python3.8/site-packages/flask_bootstrap/templates/bootstrap/base.html", line 20, in block "html"
    {% block body -%}
  File "/home/szwhite/shayblog/sbvenv/lib/python3.8/site-packages/flask_bootstrap/templates/bootstrap/base.html", line 21, in block "body"
    {% block navbar %}
  File "/home/szwhite/shayblog/myapp/templates/base.html", line 17, in block "navbar"
    <a class="navbar-brand" href="{{ url_for('index') }}">ShayBlog</a>
  File "/home/szwhite/shayblog/sbvenv/lib/python3.8/site-packages/flask/helpers.py", line 370, in url_for
    return appctx.app.handle_url_build_error(error, endpoint, values)
  File "/home/szwhite/shayblog/sbvenv/lib/python3.8/site-packages/flask/app.py", line 2216, in handle_url_build_error
    reraise(exc_type, exc_value, tb)
  File "/home/szwhite/shayblog/sbvenv/lib/python3.8/site-packages/flask/_compat.py", line 39, in reraise
    raise value
  File "/home/szwhite/shayblog/sbvenv/lib/python3.8/site-packages/flask/helpers.py", line 357, in url_for
    rv = url_adapter.build(
  File "/home/szwhite/shayblog/sbvenv/lib/python3.8/site-packages/werkzeug/routing.py", line 2179, in build
    raise BuildError(endpoint, values, method, self)
werkzeug.routing.BuildError: Could not build url for endpoint 'index'. Did you mean 'main.index' instead?
2021-05-20 09:26:48,955 INFO: ShayBlog startup [in /home/szwhite/shayblog/myapp/__init__.py:70]
2021-05-20 13:06:39,567 INFO: ShayBlog startup [in /home/szwhite/shayblog/myapp/__init__.py:70]
2021-05-20 16:26:26,562 INFO: ShayBlog startup [in /home/szwhite/shayblog/myapp/__init__.py:72]
2021-05-20 16:39:37,493 INFO: ShayBlog startup [in /home/szwhite/shayblog/myapp/__init__.py:72]
2021-05-20 16:39:44,605 ERROR: Exception on /auth/login [GET] [in /home/szwhite/shayblog/sbvenv/lib/python3.8/site-packages/flask/app.py:1891]
Traceback (most recent call last):
  File "/home/szwhite/shayblog/sbvenv/lib/python3.8/site-packages/flask/app.py", line 2447, in wsgi_app
    response = self.full_dispatch_request()
  File "/home/szwhite/shayblog/sbvenv/lib/python3.8/site-packages/flask/app.py", line 1952, in full_dispatch_request
    rv = self.handle_user_exception(e)
  File "/home/szwhite/shayblog/sbvenv/lib/python3.8/site-packages/flask/app.py", line 1821, in handle_user_exception
    reraise(exc_type, exc_value, tb)
  File "/home/szwhite/shayblog/sbvenv/lib/python3.8/site-packages/flask/_compat.py", line 39, in reraise
    raise value
  File "/home/szwhite/shayblog/sbvenv/lib/python3.8/site-packages/flask/app.py", line 1950, in full_dispatch_request
    rv = self.dispatch_request()
  File "/home/szwhite/shayblog/sbvenv/lib/python3.8/site-packages/flask/app.py", line 1936, in dispatch_request
    return self.view_functions[rule.endpoint](**req.view_args)
  File "/home/szwhite/shayblog/myapp/auth/routes.py", line 27, in login
    return render_template('auth/login.html', title='Sign In', form=form)
  File "/home/szwhite/shayblog/sbvenv/lib/python3.8/site-packages/flask/templating.py", line 138, in render_template
    ctx.app.jinja_env.get_or_select_template(template_name_or_list),
  File "/home/szwhite/shayblog/sbvenv/lib/python3.8/site-packages/jinja2/environment.py", line 930, in get_or_select_template
    return self.get_template(template_name_or_list, parent, globals)
  File "/home/szwhite/shayblog/sbvenv/lib/python3.8/site-packages/jinja2/environment.py", line 883, in get_template
    return self._load_template(name, self.make_globals(globals))
  File "/home/szwhite/shayblog/sbvenv/lib/python3.8/site-packages/jinja2/environment.py", line 857, in _load_template
    template = self.loader.load(self, name, globals)
  File "/home/szwhite/shayblog/sbvenv/lib/python3.8/site-packages/jinja2/loaders.py", line 115, in load
    source, filename, uptodate = self.get_source(environment, name)
  File "/home/szwhite/shayblog/sbvenv/lib/python3.8/site-packages/flask/templating.py", line 60, in get_source
    return self._get_source_fast(environment, template)
  File "/home/szwhite/shayblog/sbvenv/lib/python3.8/site-packages/flask/templating.py", line 89, in _get_source_fast
    raise TemplateNotFound(template)
jinja2.exceptions.TemplateNotFound: auth/login.html
2021-05-20 16:47:11,925 INFO: ShayBlog startup [in /home/szwhite/shayblog/myapp/__init__.py:72]
